Workbook

Sheet Tổng quan
A1: Tổng quan tiến độ - Trở thành Business Analyst ứng dụng AI trong công việc (4 tuần, 20 bài)
A3: Tuần | B3: Số mục | C3: Đã xong | D3: % hoàn thành
A4: Tuần 1: Nền tảng Business Analyst thời AI | B4: =COUNTIF('Theo dõi tiến độ'!E6:E85,"Chưa")+COUNTIF('Theo dõi tiến độ'!E6:E85,"Xong") | C4: =COUNTIF('Theo dõi tiến độ'!E6:E85,"Xong") | D4: =IF(B4=0,0,C4/B4)
A5: Tuần 2: Dùng AI cho thu thập và phân tích yêu cầu | B5: =COUNTIF('Theo dõi tiến độ'!E87:E163,"Chưa")+COUNTIF('Theo dõi tiến độ'!E87:E163,"Xong") | C5: =COUNTIF('Theo dõi tiến độ'!E87:E163,"Xong") | D5: =IF(B5=0,0,C5/B5)
A6: Tuần 3: AI cho phân tích dữ liệu và trực quan hóa | B6: =COUNTIF('Theo dõi tiến độ'!E165:E249,"Chưa")+COUNTIF('Theo dõi tiến độ'!E165:E249,"Xong") | C6: =COUNTIF('Theo dõi tiến độ'!E165:E249,"Xong") | D6: =IF(B6=0,0,C6/B6)
A7: Tuần 4: Tự động hóa, đạo đức và dự án thực tế | B7: =COUNTIF('Theo dõi tiến độ'!E251:E329,"Chưa")+COUNTIF('Theo dõi tiến độ'!E251:E329,"Xong") | C7: =COUNTIF('Theo dõi tiến độ'!E251:E329,"Xong") | D7: =IF(B7=0,0,C7/B7)
A8: TỔNG | B8: =SUM(B4:B7) | C8: =SUM(C4:C7) | D8: =C8/B8

Sheet Theo dõi tiến độ
A1: Trở thành Business Analyst ứng dụng AI trong công việc (LearningVN) - Theo dõi tiến độ chi tiết
A2: Mỗi bài gồm: Bài đọc (các đề mục bên dưới) và Quiz. Chọn Chưa/Xong ở cột Trạng thái của từng mục; dòng tuần và dòng bài tự tính % hoàn thành.
A4: Tuần | B4: Bài | C4: Phần / Đề mục | D4: Tên đề mục | E4: Trạng thái | F4: Ngày học | G4: % hoàn thành | H4: Ghi chú
A5: Tuần 1: Nền tảng Business Analyst thời AI | G5: =COUNTIF(E7:E85,"Xong")/COUNTA(E7:E85)
A6: Tuần 1 | B6: 1 | C6: BÀI HỌC | D6: Business Analyst là ai và làm gì trong kỷ nguyên AI | E6: =IF(G6=1,"Hoàn thành",IF(G6>0,"Đang học","Chưa học")) | G6: =COUNTIF(E7:E21,"Xong")/COUNTA(E7:E21)
A7: Tuần 1 | B7: 1 | C7: Bài đọc | D7: Giới thiệu | E7: Chưa
A8: Tuần 1 | B8: 1 | C8: Bài đọc | D8: Bạn sẽ học được gì? | E8: Chưa
A9: Tuần 1 | B9: 1 | C9: Bài đọc | D9: 1. Business Analyst - "người phiên dịch" của dự án | E9: Chưa
A10: Tuần 1 | B10: 1 | C10: Bài đọc | D10: 2. Một ngày của Business Analyst làm những gì? | E10: Chưa
A11: Tuần 1 | B11: 1 | C11: Bài đọc | D11: 3. Kỹ năng cốt lõi của một Business Analyst | E11: Chưa
A12: Tuần 1 | B12: 1 | C12: Bài đọc | D12: 4. Phân biệt BA với các vai trò dễ nhầm | E12: Chưa
A13: Tuần 1 | B13: 1 | C13: Bài đọc | D13: 5. Kỷ nguyên AI thay đổi nghề BA như thế nào? | E13: Chưa
A14: Tuần 1 | B14: 1 | C14: Bài đọc | D14: Nhìn sâu hơn | E14: Chưa
A15: Tuần 1 | B15: 1 | C15: Bài đọc | D15: Thực hành | E15: Chưa
A16: Tuần 1 | B16: 1 | C16: Bài đọc | D16: Hiểu lầm thường gặp | E16: Chưa
A17: Tuần 1 | B17: 1 | C17: Bài đọc | D17: Thực hành tốt nhất / Mẹo ghi nhớ | E17: Chưa
A18: Tuần 1 | B18: 1 | C18: Bài đọc | D18: Tóm tắt trực quan | E18: Chưa
... A21: Tuần 1 | B21: 1 | C21: Quiz | D21: Làm bài kiểm tra cuối bài | E21: Chưa
A22: Tuần 1 | B22: 2 | C22: BÀI HỌC | D22: Quy trình nghiệp vụ và vòng đời dự án (SDLC, Agile) cho BA | E22: =IF(G22=1,"Hoàn thành",IF(G22>0,"Đang học","Chưa học")) | G22: =COUNTIF(E23:E37,"Xong")/COUNTA(E23:E37)
A23: Tuần 1 | B23: 2 | C23: Bài đọc | D23: Giới thiệu | E23: Chưa
A24: Tuần 1 | B24: 2 | C24: Bài đọc | D24: Bạn sẽ học được gì? | E24: Chưa
A25: Tuần 1 | B25: 2 | C25: Bài đọc | D25: 1. SDLC - vòng đời của một dự án phần mềm | E25: Chưa
A26: Tuần 1 | B26: 2 | C26: Bài đọc | D26: 2. Waterfall - làm tuần tự như thác nước | E26: Chưa
A27: Tuần 1 | B27: 2 | C27: Bài đọc | D27: 3. Agile - làm linh hoạt, giao từng phần nhỏ | E27: Chưa
A28: Tuần 1 | B28: 2 | C28: Bài đọc | D28: 4. Scrum - khung làm việc Agile phổ biến nhất | E28: Chưa
A29: Tuần 1 | B29: 2 | C29: Bài đọc | D29: 5. BA làm gì trong một nhóm Agile/Scrum? | E29: Chưa
A30: Tuần 1 | B30: 2 | C30: Bài đọc | D30: Nhìn sâu hơn | E30: Chưa
A31: Tuần 1 | B31: 2 | C31: Bài đọc | D31: Thực hành | E31: Chưa
A32: Tuần 1 | B32: 2 | C32: Bài đọc | D32: Hiểu lầm thường gặp | E32: Chưa
A33: Tuần 1 | B33: 2 | C33: Bài đọc | D33: Thực hành tốt nhất / Mẹo ghi nhớ | E33: Chưa
A34: Tuần 1 | B34: 2 | C34: Bài đọc | D34: Tóm tắt trực quan | E34: Chưa
... A37: Tuần 1 | B37: 2 | C37: Quiz | D37: Làm bài kiểm tra cuối bài | E37: Chưa
A38: Tuần 1 | B38: 3 | C38: BÀI HỌC | D38: Bộ công cụ và tư duy phân tích của Business Analyst | E38: =IF(G38=1,"Hoàn thành",IF(G38>0,"Đang học","Chưa học")) | G38: =COUNTIF(E39:E53,"Xong")/COUNTA(E39:E53)
A39: Tuần 1 | B39: 3 | C39: Bài đọc | D39: Giới thiệu | E39: Chưa
A40: Tuần 1 | B40: 3 | C40: Bài đọc | D40: Bạn sẽ học được gì? | E40: Chưa
A41: Tuần 1 | B41: 3 | C41: Bài đọc | D41: 1. Tư duy phân tích - "cơ bắp" của BA | E41: Chưa
A42: Tuần 1 | B42: 3 | C42: Bài đọc | D42: 2. Các khung phân tích kinh điển | E42: Chưa
A43: Tuần 1 | B43: 3 | C43: Bài đọc | D43: 3. Sơ đồ quy trình (Flowchart) - kể chuyện bằng hình | E43: Chưa
A44: Tuần 1 | B44: 3 | C44: Bài đọc | D44: 4. Công cụ phần mềm BA thường dùng | E44: Chưa
A45: Tuần 1 | B45: 3 | C45: Bài đọc | D45: 5. AI đang "tăng lực" cho các công cụ này | E45: Chưa
...
